Workbook

Sheet Dados
A1: IBGE | B1: Município | C1: Latitude | D1: Longitude | E1: Área colhida HE | F1: Quantidade produzida Ton | G1: Regiao Cafeeira | H1: CNPJ | I1: Situacao do Cadastro | J1: Grau | K1: Denominação | L1: Razao Social | M1: Codigo Sindical | N1: Central sindical | O1: Confederacao | P1: Federacao | Q1: Funcionamento da direcao | R1: Número total de dirigentes eleitos | S1: Número de votos da chapa vencedora | T1: Forma de Eleicao | U1: Numero de Chapas | V1: Total de Sindicalizados / Filiados | W1: Total de Votantes | X1: Area Geoeconômica | Y1: Grupo | Z1: Classe | AA1: Categoria | AB1: CEP | AC1: UF da sede | AD1: Localidade da sede | AE1: Bairro | AF1: Logradouro | AG1: Número | AH1: Complemento | AI1: Email | AJ1: Telefone principal | AK1: Site | AL1: Data de Início do Mandato | AM1: Data Fim do Mandato | AN1: Presidente | AO1: Abrangencia | AP1: Base Territorial
A2: =_xlfn.XLOOKUP(AD2,'Municipios MG'!$B$2:$B$853,'Municipios MG'!$A$2:$A$853) -> 3145604 | B2: =_xlfn.XLOOKUP(AD2,'Municipios MG'!$B$2:$B$853,'Municipios MG'!$B$2:$B$853) -> Oliveira | C2: =_xlfn.XLOOKUP(AD2,'Municipios MG'!$B$2:$B$853,'Municipios MG'!$C$2:$C$853) -> -20.697516 | D2: =_xlfn.XLOOKUP(AD2,'Municipios MG'!$B$2:$B$853,'Municipios MG'!$D$2:$D$853) -> -44.826411 | E2: =_xlfn.XLOOKUP(A2,Planilha3!$A$2:$A$5543,Planilha3!$C$2:$C$5543) -> 7035 | F2: =_xlfn.XLOOKUP(A2,Planilha3!$A$2:$A$5543,Planilha3!$E$2:$E$5543) -> 10764 | G2: =_xlfn.XLOOKUP(A2,'Municipios MG'!$A$2:$A$853,'Municipios MG'!$E$2:$E$853) -> Campo das Vertentes | H2: 20.919.320/0001-57 | I2: ATIVO | J2: SINDICATO | K2: STR Oliveira/MG - Sindicato dos Trabalhadores Rurais de Oliveira/MG | L2: SINDICATO DOS TRABALHADORES RURAIS DE OLIVEIRA | M2: 000.000.000.00000-0 | N2: - | O2: Confederação Nacional dos Trabalhadores Rurais Agricultores e Agricultoras Familiares | P2: FETAEMG - Federação dos Trabalhadores na Agricultura do Estado de Minas Gerais | Q2: PRESIDENCIALISMO | R2: 15 | S2: 144 | T2: DIRETA | U2: 1 | V2: 3699 | W2: 144 | X2: RURAL | Y2: TRABALHADORES | Z2: RURAL | AA2: Profissional dos Trabalhadores Rurais, do Plano da CONTAG | AB2: 35540-000 | AC2: MG | AD2: Oliveira | AE2: - | AF2: Rua Francisco Cambraia Campos | AG2: 545 | AH2: Centro | AI2: stroliveira@hotmail.com | AJ2: 3733314343 | AK2: - | AL2: 08/10/2023 | AM2: 07/10/2027 | AN2: SONIA APARECIDA NASCIMENTO STACANELLI | AO2: MUNICIPAL | AP2: Minas Gerais: Oliveira
A3: =_xlfn.XLOOKUP(AD3,'Municipios MG'!$B$2:$B$853,'Municipios MG'!$A$2:$A$853) -> 3161205 | B3: =_xlfn.XLOOKUP(AD3,'Municipios MG'!$B$2:$B$853,'Municipios MG'!$B$2:$B$853) -> São Francisco de Paula | C3: =_xlfn.XLOOKUP(AD3,'Municipios MG'!$B$2:$B$853,'Municipios MG'!$C$2:$C$853) -> -20.713532 | D3: =_xlfn.XLOOKUP(AD3,'Municipios MG'!$B$2:$B$853,'Municipios MG'!$D$2:$D$853) -> -44.982631 | E3: =_xlfn.XLOOKUP(A3,Planilha3!$A$2:$A$5543,Planilha3!$C$2:$C$5543) -> 2850 | F3: =_xlfn.XLOOKUP(A3,Planilha3!$A$2:$A$5543,Planilha3!$E$2:$E$5543) -> 4617 | G3: =_xlfn.XLOOKUP(A3,'Municipios MG'!$A$2:$A$853,'Municipios MG'!$E$2:$E$853) -> Campo das Vertentes | H3: 20.919.296/0001-56 | I3: ATIVO | J3: SINDICATO | K3: STR - STR SÃO FRANCISCO PAULA | L3: SINDICATO DOS TRABALHADORES RURAIS, ASSALARIADOS AGRICULTORE | M3: 000.000.000.00000-0 | N3: CTB - Central dos Trabalhadores e Trabalhadoras do Brasil | O3: Confederação Nacional dos Trabalhadores Rurais Agricultores e Agricultoras Familiares | P3: FETAEMG - Federação dos Trabalhadores na Agricultura do Estado de Minas Gerais | Q3: PRESIDENCIALISMO | R3: 16 | S3: 73 | T3: DIRETA | U3: 1 | V3: 1655 | W3: 74 | X3: RURAL | Y3: TRABALHADORES | Z3: RURAL | AA3: Profissional dos Trabalhadores Rurais, do Plano da CONTAG | AB3: 35543-000 | AC3: MG | AD3: São Francisco de Paula | AE3: CENTRO | AF3: RUA DA GLORIA | AG3: 79 | AH3: - | AI3: sindicatosaofrancisco2021@gmail.com | AJ3: 3733321380 | AK3: - | AL3: 08/03/2026 | AM3: 07/03/2030 | AN3: SIMONE ALVES DE ARAUJO | AO3: MUNICIPAL | AP3: Minas Gerais: São Francisco de Paula
A4: =_xlfn.XLOOKUP(AD4,'Municipios MG'!$B$2:$B$853,'Municipios MG'!$A$2:$A$853) -> 3114006 | B4: =_xlfn.XLOOKUP(AD4,'Municipios MG'!$B$2:$B$853,'Municipios MG'!$B$2:$B$853) -> Carmo da Mata | C4: =_xlfn.XLOOKUP(AD4,'Municipios MG'!$B$2:$B$853,'Municipios MG'!$C$2:$C$853) -> -20.55921 | D4: =_xlfn.XLOOKUP(AD4,'Municipios MG'!$B$2:$B$853,'Municipios MG'!$D$2:$D$853) -> -44.868383 | E4: =_xlfn.XLOOKUP(A4,Planilha3!$A$2:$A$5543,Planilha3!$C$2:$C$5543) -> 900 | F4: =_xlfn.XLOOKUP(A4,Planilha3!$A$2:$A$5543,Planilha3!$E$2:$E$5543) -> 1458 | G4: =_xlfn.XLOOKUP(A4,'Municipios MG'!$A$2:$A$853,'Municipios MG'!$E$2:$E$853) -> Campo das Vertentes | H4: 20.919.205/0001-82 | I4: ATIVO | J4: SINDICATO | K4: STR - Sindicato dos Trabalhadores Rurais de Carmo da Mata | L4: SINDICATO DOS TRABALHADORES RURAIS DE CARMO DA MATA | M4: 000.000.000.00000-0 | N4: CTB - Central dos Trabalhadores e Trabalhadoras do Brasil | O4: Confederação Nacional dos Trabalhadores Rurais Agricultores e Agricultoras Familiares | P4: FETAEMG - Federação dos Trabalhadores na Agricultura do Estado de Minas Gerais | Q4: PRESIDENCIALISMO | R4: 16 | S4: 54 | T4: DIRETA | U4: 1 | V4: 2184 | W4: 54 | X4: RURAL | Y4: TRABALHADORES | Z4: RURAL | AA4: trabalhadores e trabalhadoras rurais: os assalariados e assalariadas rurais, empregados permanentes, safristas e eventuais na agricultura, criação de animais, silvicultura, hortifruticultura e extrativismo rural; e agricultores e_x000D_ agricultoras que exerçam atividades individualmente ou em regime de economia familiar, na qualidade de pequenos produtores, proprietários, posseiros, assentados, meeiros parceiros, arrendatários, comodatários, extrativistas e os aposentados (as) rurais | AB4: 35547-000 | AC4: MG | AD4: Carmo da Mata | AE4: Centro | AF4: Rua Felisberto Corrêa Vaz | AG4: 245 | AH4: Casa | AI4: sdostrabalhadoresrurais@yahoo.com.br | AJ4: 3733831042 | AK4: - | AL4: 18/06/2026 | AM4: 17/06/2030 | AN4: MARIA HELENA DA SILVA | AO4: MUNICIPAL | AP4: Minas Gerais: Carmo da Mata
A5: =_xlfn.XLOOKUP(AD5,'Municipios MG'!$B$2:$B$853,'Municipios MG'!$A$2:$A$853) -> 3112208 | B5: =_xlfn.XLOOKUP(AD5,'Municipios MG'!$B$2:$B$853,'Municipios MG'!$B$2:$B$853) -> Capela Nova | C5: =_xlfn.XLOOKUP(AD5,'Municipios MG'!$B$2:$B$853,'Municipios MG'!$C$2:$C$853) -> -20.916668 | D5: =_xlfn.XLOOKUP(AD5,'Municipios MG'!$B$2:$B$853,'Municipios MG'!$D$2:$D$853) -> -43.612422 | E5: =_xlfn.XLOOKUP(A5,Planilha3!$A$2:$A$5543,Planilha3!$C$2:$C$5543) -> 450 | F5: =_xlfn.XLOOKUP(A5,Planilha3!$A$2:$A$5543,Planilha3!$E$2:$E$5543) -> 675 | G5: =_xlfn.XLOOKUP(A5,'Municipios MG'!$A$2:$A$853,'Municipios MG'!$E$2:$E$853) -> Campo das Vertentes | H5: 19.557.537/0001-85 | I5: ATIVO | J5: SINDICATO | K5: STR Capela Nova/MG - Sindicato dos Trabalhadores Rurais, Assalariados e Agricultores Familiares de Capela Nova e Caranaíba/MG | L5: SINDICATO DOS TRABALHADORES RURAIS ASSALARIADOS AGRICULTORES | M5: 000.000.000.00000-0 | N5: CTB - Central dos Trabalhadores e Trabalhadoras do Brasil | O5: Confederação Nacional dos Trabalhadores Rurais Agricultores e Agricultoras Familiares | P5: FETAEMG - Federação dos Trabalhadores na Agricultura do Estado de Minas Gerais | Q5: PRESIDENCIALISMO | R5: 12 | S5: 108 | T5: DECISAO_ASSEMBLEIA | U5: 1 | V5: 1800 | W5: 108 | X5: RURAL | Y5: TRABALHADORES | Z5: RURAL | AA5: São considerados Trabalhadores Rurais, os que exercem atividades como Assalariados na Agricultura, Pecuária e Similares, na Produção Rural, bem como Agricultores Familiares, Proprietários ou não, que exerçam atividade Rural, Individualmente ou em Regime de Economia Familiar, assim entendido o trabalho dos membros da família, executando em condições de mútua dependência e colaboração, ainda que com a ajuda eventual de terceiros, Trabalhadores no Reflorestamento, Hortifrutigranjeiros, Assentados e Parceleiros da Reforma Agrária, Pescadores e Garimpeiros Artensanais que Trabalham por Conta Própria e não Tenham Empregados, Trabalhadores na Área da Cana e da Avicultura, Tratorista Rural e os que Trabalham com Artesanato Rural | AB5: 36290-000 | AC5: MG | AD5: Capela Nova | AE5: - | AF5: Rua Avelina Damascena | AG5: 302 | AH5: Centro | AI5: strcapelanova@hotmail.com | AJ5: 3137271209 | AK5: - | AL5: 11/04/2023 | AM5: 10/04/2027 | AN5: ROBSON DOS REMEDIOS E SOUZA | AO5: INTERMUNICIPAL | AP5: Minas Gerais: Capela Nova, Caranaíba
A6: =_xlfn.XLOOKUP(AD6,'Municipios MG'!$B$2:$B$853,'Municipios MG'!$A$2:$A$853) -> 3152303 | B6: =_xlfn.XLOOKUP(AD6,'Municipios MG'!$B$2:$B$853,'Municipios MG'!$B$2:$B$853) -> Porto Firme | C6: =_xlfn.XLOOKUP(AD6,'Municipios MG'!$B$2:$B$853,'Municipios MG'!$C$2:$C$853) -> -20.668267 | D6: =_xlfn.XLOOKUP(AD6,'Municipios MG'!$B$2:$B$853,'Municipios MG'!$D$2:$D$853) -> -43.091411 | E6: =_xlfn.XLOOKUP(A6,Planilha3!$A$2:$A$5543,Planilha3!$C$2:$C$5543) -> 450 | F6: =_xlfn.XLOOKUP(A6,Planilha3!$A$2:$A$5543,Planilha3!$E$2:$E$5543) -> 594 | G6: =_xlfn.XLOOKUP(A6,'Municipios MG'!$A$2:$A$853,'Municipios MG'!$E$2:$E$853) -> Campo das Vertentes | H6: 19.484.351/0001-43 | I6: ATIVO | J6: SINDICATO | K6: STR - STR PORTO FIRME | L6: SINDICATO DOS TRABALHADORES RURAIS DE PORTO FIRME | M6: 000.000.000.00000-0 | N6: CTB - Central dos Trabalhadores e Trabalhadoras do Brasil | O6: Confederação Nacional dos Trabalhadores Rurais Agricultores e Agricultoras Familiares | P6: FETAEMG - Federação dos Trabalhadores na Agricultura do Estado de Minas Gerais | Q6: PRESIDENCIALISMO | R6: 12 | S6: 670 | T6: DECISAO_ASSEMBLEIA | U6: 1 | V6: 7873 | W6: 674 | X6: RURAL | Y6: TRABALHADORES | Z6: RURAL | AA6: Profissional dos Trabalhadores Rurais, do Plano da CONTAG | AB6: 36576-000 | AC6: MG | AD6: Porto Firme | AE6: CENTRO | AF6: RUA DOM SILVERIO | AG6: 352 | AH6: - | AI6: ednasindicato@hotmail.com | AJ6: 3138931350 | AK6: - | AL6: 05/12/2023 | AM6: 05/12/2027 | AN6: MARIA DO CARMO RAMOS SIQUEIRA | AO6: MUNICIPAL | AP6: Minas Gerais: Porto Firme
A7: =_xlfn.XLOOKUP(AD7,'Municipios MG'!$B$2:$B$853,'Municipios MG'!$A$2:$A$853) -> 3133501 | B7: =_xlfn.XLOOKUP(AD7,'Municipios MG'!$B$2:$B$853,'Municipios MG'!$B$2:$B$853) -> Itapecerica | C7: =_xlfn.XLOOKUP(AD7,'Municipios MG'!$B$2:$B$853,'Municipios MG'!$C$2:$C$853) -> -20.47289 | D7: =_xlfn.XLOOKUP(AD7,'Municipios MG'!$B$2:$B$853,'Municipios MG'!$D$2:$D$853) -> -45.12468 | E7: =_xlfn.XLOOKUP(A7,Planilha3!$A$2:$A$5543,Planilha3!$C$2:$C$5543) -> 395 | F7: =_xlfn.XLOOKUP(A7,Planilha3!$A$2:$A$5543,Planilha3!$E$2:$E$5543) -> 740 | G7: =_xlfn.XLOOKUP(A7,'Municipios MG'!$A$2:$A$853,'Municipios MG'!$E$2:$E$853) -> Campo das Vertentes | H7: 21.231.980/0001-03 | I7: ATIVO | J7: SINDICATO | K7: str - str camacho e itapecerica no estado de minas gerais | L7: SINDICATO DOS TRABALHADORES RURAIS DE ITAPECERICA | M7: 000.000.000.00000-0 | N7: - | O7: Confederação Nacional dos Trabalhadores Rurais Agricultores e Agricultoras Familiares | P7: FETAEMG - Federação dos Trabalhadores na Agricultura do Estado de Minas Gerais | Q7: PRESIDENCIALISMO | R7: 12 | S7: 273 | T7: DIRETA | U7: 1 | V7: 10214 | W7: 291 | X7: RURAL | Y7: TRABALHADORES | Z7: RURAL | AA7: Profissional dos Trabalhadores Rurais, do Plano da CONTAG | AB7: 35550-000 | AC7: MG | AD7: Itapecerica | AE7: CENTRO | AF7: PRAÇA SEVERO RIBEIRO | AG7: 16 | AH7: A | AI7: sindicatoitapecerica@gmail.com | AJ7: 3733411517 | AK7: - | AL7: 01/06/2023 | AM7: 31/05/2027 | AN7: ILDEU ASSIS DOS SANTOS | AO7: INTERMUNICIPAL | AP7: Minas Gerais: Camacho, Itapecerica
A8: =_xlfn.XLOOKUP(AD8,'Municipios MG'!$B$2:$B$853,'Municipios MG'!$A$2:$A$853) -> 3116605 | B8: =_xlfn.XLOOKUP(AD8,'Municipios MG'!$B$2:$B$853,'Municipios MG'!$B$2:$B$853) -> Cláudio | C8: =_xlfn.XLOOKUP(AD8,'Municipios MG'!$B$2:$B$853,'Municipios MG'!$C$2:$C$853) -> -20.444575 | D8: =_xlfn.XLOOKUP(AD8,'Municipios MG'!$B$2:$B$853,'Municipios MG'!$D$2:$D$853) -> -44.768423 | E8: =_xlfn.XLOOKUP(A8,Planilha3!$A$2:$A$5543,Planilha3!$C$2:$C$5543) -> 330 | F8: =_xlfn.XLOOKUP(A8,Planilha3!$A$2:$A$5543,Planilha3!$E$2:$E$5543) -> 594 | G8: =_xlfn.XLOOKUP(A8,'Municipios MG'!$A$2:$A$853,'Municipios MG'!$E$2:$E$853) -> Campo das Vertentes | H8: 16.748.774/0001-35 | I8: ATIVO | J8: SINDICATO | K8: STR de Cláudio-MG - Sindicato dos Trabalhadores Rurais, Assalariados e Agricultores Familiares do Município de Cláudio ", MG | L8: SINDICATO DOS TRABALHADORES RURAIS, ASSALARIADOS E AGRICULTORES FAMILIARES DO MUNICIPIO DE CLAUDIO - MG | M8: 000.000.000.00000-0 | N8: CTB - Central dos Trabalhadores e Trabalhadoras do Brasil | O8: Confederação Nacional dos Trabalhadores Rurais Agricultores e Agricultoras Familiares | P8: FETAEMG - Federação dos Trabalhadores na Agricultura do Estado de Minas Gerais | Q8: PRESIDENCIALISMO | R8: 14 | S8: 241 | T8: DIRETA | U8: 1 | V8: 897 | W8: 246 | X8: RURAL | Y8: TRABALHADORES | Z8: RURAL | AA8: Trabalhadores Rurais, os que exercem atividade como Assalariados na Agricultura, Pecuária e Similares, na Produção Rural, bem como os Agricultores Familiares, Proprietários ou não, que exerçam atividade Rural, individualmente ou em regime de Economia Familiar, assim entendido o trabalho dos membros da mesma família, executando em condições de mútua dependência e colaboração, ainda que com ajuda eventual de terceiros, Trabalhadores no Reflorestameto, Hortifrutigranjeiros, Assentados e Parceleiros da Reforma Agrária, Pescadores e Garimpeiros Artesanais que trabalham por conta própria e não tenham empregados, trabalhadores na área da cana e da Avicultura, Tratorista Rural e os que trabalham com Artesanato Rural. | AB8: 35530-000 | AC8: MG | AD8: Cláudio | AE8: Centro | AF8: Rua Goiás | AG8: 109 | AH8: casa | AI8: sindicatoclaudio@hotmail.com | AJ8: 3733811513 | AK8: - | AL8: 08/04/2024 | AM8: 07/04/2028 | AN8: MAURILO MARCELINO TOMAZ | AO8: MUNICIPAL | AP8: Minas Gerais: Cláudio
A9: =_xlfn.XLOOKUP(AD9,'Municipios MG'!$B$2:$B$853,'Municipios MG'!$A$2:$A$853) -> 3153103 | B9: =_xlfn.XLOOKUP(AD9,'Municipios MG'!$B$2:$B$853,'Municipios MG'!$B$2:$B$853) -> Presidente Bernardes | C9: =_xlfn.XLOOKUP(AD9,'Municipios MG'!$B$2:$B$853,'Municipios MG'!$C$2:$C$853) -> -20.765678 | D9: =_xlfn.XLOOKUP(AD9,'Municipios MG'!$B$2:$B$853,'Municipios MG'!$D$2:$D$853) -> -43.190056 | E9: =_xlfn.XLOOKUP(A9,Planilha3!$A$2:$A$5543,Planilha3!$C$2:$C$5543) -> 300 | F9: =_xlfn.XLOOKUP(A9,Planilha3!$A$2:$A$5543,Planilha3!$E$2:$E$5543) -> 360 | G9: =_xlfn.XLOOKUP(A9,'Municipios MG'!$A$2:$A$853,'Municipios MG'!$E$2:$E$853) -> Campo das Vertentes | H9: 16.760.449/0001-98 | I9: ATIVO | J9: SINDICATO | K9: STR Presidente Bernardes/MG - Sindicato dos Trabalhadores Rurais de Presidente Bernardes/MG | L9: SINDICATO DOS TRABALHADORES RURAIS DE PRES BERNARDES | M9: 000.000.000.00000-0 | N9: - | O9: Confederação Nacional dos Trabalhadores Rurais Agricultores e Agricultoras Familiares | P9: FETAEMG - Federação dos Trabalhadores na Agricultura do Estado de Minas Gerais | Q9: PRESIDENCIALISMO | R9: 11 | S9: 648 | T9: DECISAO_ASSEMBLEIA | U9: 1 | V9: 1580 | W9: 659 | X9: RURAL | Y9: TRABALHADORES | Z9: RURAL | AA9: Categoria Profissional dos Trabalhadores Rurais do Plano da CONTAG | AB9: 36475-000 | AC9: MG | AD9: Presidente Bernardes | AE9: - | AF9: Rua São José | AG9: 41 | AH9: Centro | AI9: sindicatobernardes@hotmail.com | AJ9: 3235381105 | AK9: - | AL9: 27/01/2024 | AM9: 26/01/2028 | AN9: CARLOS EVANGELINO DE SOUZA | AO9: MUNICIPAL | AP9: Minas Gerais: Presidente Bernardes
A10: =_xlfn.XLOOKUP(AD10,'Municipios MG'!$B$2:$B$853,'Municipios MG'!$A$2:$A$853) -> 3115201 | B10: =_xlfn.XLOOKUP(AD10,'Municipios MG'!$B$2:$B$853,'Municipios MG'!$B$2:$B$853) -> Conceição da Barra de Minas | C10: =_xlfn.XLOOKUP(AD10,'Municipios MG'!$B$2:$B$853,'Municipios MG'!$C$2:$C$853) -> -21.131769 | D10: =_xlfn.XLOOKUP(AD10,'Municipios MG'!$B$2:$B$853,'Municipios MG'!$D$2:$D$853) -> -44.477808 | E10: =_xlfn.XLOOKUP(A10,Planilha3!$A$2:$A$5543,Planilha3!$C$2:$C$5543) -> 275 | F10: =_xlfn.XLOOKUP(A10,Planilha3!$A$2:$A$5543,Planilha3!$E$2:$E$5543) -> 462 | G10: =_xlfn.XLOOKUP(A10,'Municipios MG'!$A$2:$A$853,'Municipios MG'!$E$2:$E$853) -> Campo das Vertentes | H10: 07.681.707/0001-50 | I10: ATIVO | J10: SINDICATO | K10: Sindicato dos Trabalhadores Rurais, Assalariados e Agricultores Familiares do Município de Conceição da Barra de Minas /MG | L10: SINDICATO DOS TRABALHADORES RURAIS, ASSALARIADOS E AGRICULTORES FAMILIARES DO MUNICIPIO DE CONCEICAO DA BARRA DE MINAS/MG | M10: 000.000.000.00000-0 | N10: - | O10: - | P10: - | Q10: PRESIDENCIALISMO | R10: 15 | S10: 47 | T10: DIRETA | U10: 1 | V10: 47 | W10: 47 | X10: RURAL | Y10: TRABALHADORES | Z10: RURAL | AA10: Profissional dos Trabalhadores e Trabalhadoras Rurais ativos e inativos: assalariados e assalariadas rurais, empregados permanentes, safristas e eventuais na agricultura, criação de animais, hortifruticultura; e agricultores e agricultoras que exerçam atividades individualmente ou em regime de economia familiar, na qualidade de pequenos produtores, proprietários até dois módulos rurais, posseiros, assentados, meeiros, parceiros, arrendatários, comodatários e os aposentados(as) rurais. | AB10: 36360-000 | AC10: MG | AD10: Conceição da Barra de Minas | AE10: CENTRO | AF10: RUA PREFEITO ANTONIO SILVA | AG10: 66 | AH10: A | AI10: sindruralcbm@yahoo.com.br | AJ10: 32984873328 | AK10: - | AL10: 06/07/2022 | AM10: 05/07/2026 | AN10: RENATO MAURO DA SILVA | AO10: MUNICIPAL | AP10: Minas Gerais: Conceição da Barra de Minas
A11: =_xlfn.XLOOKUP(AD11,'Municipios MG'!$B$2:$B$853,'Municipios MG'!$A$2:$A$853) -> 3150802 | B11: =_xlfn.XLOOKUP(AD11,'Municipios MG'!$B$2:$B$853,'Municipios MG'!$B$2:$B$853) -> Piranga | C11: =_xlfn.XLOOKUP(AD11,'Municipios MG'!$B$2:$B$853,'Municipios MG'!$C$2:$C$853) -> -20.685144 | D11: =_xlfn.XLOOKUP(AD11,'Municipios MG'!$B$2:$B$853,'Municipios MG'!$D$2:$D$853) -> -43.287346 | E11: =_xlfn.XLOOKUP(A11,Planilha3!$A$2:$A$5543,Planilha3!$C$2:$C$5543) -> 200 | F11: =_xlfn.XLOOKUP(A11,Planilha3!$A$2:$A$5543,Planilha3!$E$2:$E$5543) -> 360 | G11: =_xlfn.XLOOKUP(A11,'Municipios MG'!$A$2:$A$853,'Municipios MG'!$E$2:$E$853) -> Campo das Vertentes | H11: 20.131.991/0001-59 | I11: ATIVO | J11: SINDICATO | K11: STRAAF PIRANGA-MG - Sindicato dos Trabalhadores Rurais, Assalariados e Agricultores Familiares do Município de Piranga", MG | L11: SINDICATO DOS TRABALHADORES RURAIS,ASSALARIADOS E AGRICULTORES FAMILIARES DE PIRANGA | M11: 000.000.000.00000-0 | N11: CTB - Central dos Trabalhadores e Trabalhadoras do Brasil | O11: Confederação Nacional dos Trabalhadores Rurais Agricultores e Agricultoras Familiares | P11: FETAEMG - Federação dos Trabalhadores na Agricultura do Estado de Minas Gerais | Q11: PRESIDENCIALISMO | R11: 12 | S11: 1374 | T11: DIRETA | U11: 1 | V11: 10493 | W11: 1379 | X11: RURAL | Y11: TRABALHADORES | Z11: RURAL | AA11: São considerados Trabalhadores Rurais, os que exercem atividade como Assalariados na Agricultura, Pecuária e Similares, na Produção Rural, bem como os Agricultores Familiares, Proprietários ou não, que exerçam atividade Rural, individualmente ou em regime economia familiar, assim entendido o trabalho dos membros da família, executando em condições de mútua dependência e colaboração, ainda com ajuda eventual de terceiros, Trabalhadores no Reflorestamento, Hortifrutigranjeiros, assentados e parceleiros da Reforma Agrária, Pescadores e Garimpeiros Artesanais que trabalham por conta própria e não tenham Empregados, Trabalhadores na Área da Cana e da Avicultura, Tratorista Rural e os que Trabalham com Artesanato Rural. | AB11: 36480-000 | AC11: MG | AD11: Piranga | AE11: CENTRO | AF11: RUA JOSÉ EUCLIDES | AG11: 21 | AH11: - | AI11: sindicatopirangamg@gmail.com | AJ11: 3137461391 | AK11: - | AL11: 14/12/2023 | AM11: 13/12/2027 | AN11: FRANCISCO LOURIVAL RIBEIRO | AO11: MUNICIPAL | AP11: Minas Gerais: Piranga
A12: =_xlfn.XLOOKUP(AD12,'Municipios MG'!$B$2:$B$853,'Municipios MG'!$A$2:$A$853) -> 3128204 | B12: =_xlfn.XLOOKUP(AD12,'Municipios MG'!$B$2:$B$853,'Municipios MG'!$B$2:$B$853) -> Guaraciaba | C12: =_xlfn.XLOOKUP(AD12,'Municipios MG'!$B$2:$B$853,'Municipios MG'!$C$2:$C$853) -> -20.571704 | D12: =_xlfn.XLOOKUP(AD12,'Municipios MG'!$B$2:$B$853,'Municipios MG'!$D$2:$D$853) -> -43.011282 | E12: =_xlfn.XLOOKUP(A12,Planilha3!$A$2:$A$5543,Planilha3!$C$2:$C$5543) -> 130 | F12: =_xlfn.XLOOKUP(A12,Planilha3!$A$2:$A$5543,Planilha3!$E$2:$E$5543) -> 234 | G12: =_xlfn.XLOOKUP(A12,'Municipios MG'!$A$2:$A$853,'Municipios MG'!$E$2:$E$853) -> Campo das Vertentes | H12: 04.064.224/0001-18 | I12: ATIVO | J12: SINDICATO | K12: Sindicato dos Trabalhadores Rurais de Guaraciaba/MG | L12: SINDICATO DOS TRABALHADORES RURAIS DE GUARACIABA/MG | M12: 000.000.000.00000-0 | N12: - | O12: - | P12: - | Q12: PRESIDENCIALISMO | R12: 16 | S12: 505 | T12: DIRETA | U12: 1 | V12: 4123 | W12: 528 | X12: RURAL | Y12: TRABALHADORES | Z12: RURAL | AA12: Profissional dos Trabalhadores e_x000D_ Trabalhadoras Rurais ativos e inativos: assalariados e assalariadas rurais, empregados_x000D_ permanentes, safristas e eventuais na agricultura, criação de animais, hortifruticultura;_x000D_ e agricultores e agricultoras que exerçam atividades individualmente ou em regime de_x000D_ economia familiar, na qualidade de pequenos produtores, proprietários até dois_x000D_ módulos rurais, posseiros, assentados, meeiros, parceiros, arrendatários, comodatários_x000D_ e os aposentados(as) rurais. | AB12: 35436-000 | AC12: MG | AD12: GUARACIABA | AE12: CENTRO | AF12: RUA PADRE MANOEL | AG12: 56 | AH12: - | AI12: sindicato.guara@hotmail.com | AJ12: 3138935337 | AK12: - | AL12: 16/08/2023 | AM12: 15/08/2027 | AN12: DORVALINA TEIXEIRA DA CUNHA DA SILVA | AO12: MUNICIPAL | AP12: Minas Gerais: Guaraciaba
A13: =_xlfn.XLOOKUP(AD13,'Municipios MG'!$B$2:$B$853,'Municipios MG'!$A$2:$A$853) -> 3147709 | B13: =_xlfn.XLOOKUP(AD13,'Municipios MG'!$B$2:$B$853,'Municipios MG'!$B$2:$B$853) -> Passa Tempo | C13: =_xlfn.XLOOKUP(AD13,'Municipios MG'!$B$2:$B$853,'Municipios MG'!$C$2:$C$853) -> -20.652388 | D13: =_xlfn.XLOOKUP(AD13,'Municipios MG'!$B$2:$B$853,'Municipios MG'!$D$2:$D$853) -> -44.493417 | E13: =_xlfn.XLOOKUP(A13,Planilha3!$A$2:$A$5543,Planilha3!$C$2:$C$5543) -> 120 | F13: =_xlfn.XLOOKUP(A13,Planilha3!$A$2:$A$5543,Planilha3!$E$2:$E$5543) -> 194 | G13: =_xlfn.XLOOKUP(A13,'Municipios MG'!$A$2:$A$853,'Municipios MG'!$E$2:$E$853) -> Campo das Vertentes | H13: 20.660.858/0001-90 | I13: ATIVO | J13: SINDICATO | K13: STR Passa Tempo/MG - Sindicato dos Trabalhadores Rurais de Passa Tempo/MG | L13: SINDICATO DOS TRABALHADORES RURAIS DE PASSA TEMPO | M13: 000.000.000.00000-0 | N13: - | O13: Confederação Nacional dos Trabalhadores Rurais Agricultores e Agricultoras Familiares | P13: FETAEMG - Federação dos Trabalhadores na Agricultura do Estado de Minas Gerais | Q13: PRESIDENCIALISMO | R13: 16 | S13: 68 | T13: DECISAO_ASSEMBLEIA | U13: 1 | V13: 561 | W13: 68 | X13: RURAL | Y13: TRABALHADORES | Z13: RURAL | AA13: Categoria Profissional dos Trabalhadores Rurais do Plano da CONTAG | AB13: 35537-000 | AC13: MG | AD13: Passa Tempo | AE13: - | AF13: Rua Cícero Ferreira de Resende | AG13: 07 | AH13: Centro | AI13: - | AJ13: 3733351199 | AK13: - | AL13: 05/07/2022 | AM13: 05/07/2026 | AN13: NEIDE ANTONIA DE SOUZA | AO13: MUNICIPAL | AP13: Minas Gerais: Passa Tempo
... A232: =_xlfn.XLOOKUP(AD232,'Municipios MG'!$B$2:$B$853,'Municipios MG'!$A$2:$A$853) -> 3110608 | B232: =_xlfn.XLOOKUP(AD232,'Municipios MG'!$B$2:$B$853,'Municipios MG'!$B$2:$B$853) -> Cambuí | C232: =_xlfn.XLOOKUP(AD232,'Municipios MG'!$B$2:$B$853,'Municipios MG'!$C$2:$C$853) -> -22.611097 | D232: =_xlfn.XLOOKUP(AD232,'Municipios MG'!$B$2:$B$853,'Municipios MG'!$D$2:$D$853) -> -46.058019 | E232: =_xlfn.XLOOKUP(A232,Planilha3!$A$2:$A$5543,Planilha3!$C$2:$C$5543) -> 4 | F232: =_xlfn.XLOOKUP(A232,Planilha3!$A$2:$A$5543,Planilha3!$E$2:$E$5543) -> 5 | G232: =_xlfn.XLOOKUP(A232,'Municipios MG'!$A$2:$A$853,'Municipios MG'!$E$2:$E$853) -> Sul de Minas | H232: 20.382.099/0001-40 | I232: ATIVO | J232: SINDICATO | K232: SINDICATO DOS TRABALHADORES RURAIS DE CAMBUI/MG - SINDICATO DOS TRABALHADORES RURAIS DE CAMBUI/MG | L232: SINDICATO DOS TRABALHADORES RURAIS, ASSAL E AGRIC FAMILIARES DE CAMBUI, CORREGO B JESUS E SENADOR AMARAL | M232: 000.000.000.00000-0 | N232: - | O232: - | P232: - | Q232: PRESIDENCIALISMO | R232: 12 | S232: 28 | T232: DIRETA | U232: 1 | V232: 5118 | W232: 28 | X232: RURAL | Y232: TRABALHADORES | Z232: RURAL | AA232: Profissional dos Trabalhadores Rurais, do Plano da CONTAG | AB232: 37600-000 | AC232: MG | AD232: CAMBUÍ | AE232: VL JD SAO BENEDITO | AF232: RUA VEREADOR BENEDITO ARTUR DE MELO | AG232: 145 | AH232: A | AI232: strcambui@micropic.com.br | AJ232: 3534311558 | AK232: - | AL232: 07/03/2023 | AM232: 06/03/2027 | AN232: DIONESIO ANTONIO DA SILVA | AO232: MUNICIPAL | AP232: Minas Gerais: Cambuí
A233: =_xlfn.XLOOKUP(AD233,'Municipios MG'!$B$2:$B$853,'Municipios MG'!$A$2:$A$853) -> 3106200 | B233: =_xlfn.XLOOKUP(AD233,'Municipios MG'!$B$2:$B$853,'Municipios MG'!$B$2:$B$853) -> Belo Horizonte | C233: =_xlfn.XLOOKUP(AD233,'Municipios MG'!$B$2:$B$853,'Municipios MG'!$C$2:$C$853) -> -19.937524 | D233: =_xlfn.XLOOKUP(AD233,'Municipios MG'!$B$2:$B$853,'Municipios MG'!$D$2:$D$853) -> -43.926453 | E233: =_xlfn.XLOOKUP(A233,Planilha3!$A$2:$A$5543,Planilha3!$C$2:$C$5543) -> ... | F233: =_xlfn.XLOOKUP(A233,Planilha3!$A$2:$A$5543,Planilha3!$E$2:$E$5543) -> ... | H233: 17.388.158/0001-83 | I233: ATIVO | J233: FEDERACAO | K233: FETAEMG - Federação dos Trabalhadores na Agricultura do Estado de Minas Gerais | L233: FEDERACAO DOS TRABALHADORES NA AGRIC DO ESTADO M GERAIS | M233: 000.000.000.00000-0 | N233: CTB - Central dos Trabalhadores e Trabalhadoras do Brasil | O233: Confederação Nacional dos Trabalhadores Rurais Agricultores e Agricultoras Familiares | P233: - | Q233: PRESIDENCIALISMO | R233: 47 | S233: 446 | T233: DECISAO_ASSEMBLEIA | U233: 1 | V233: 535 | W233: 457 | X233: RURAL | Y233: TRABALHADORES | Z233: RURAL | AA233: Coordenação, Representação e Integração dos Trabalhadores (as) e empregados (as) rurais e agricultores familiares, ativos (as) e aposentados (as), são considerados trabalhadores e trabalhadoras rurais: os assalariados (as) rurais, empregados permanentes, safristas e eventuais na agricultura, criação de animais, silvicultura, hortifruticultura e extrativismo rural e agricultores (as) que exerçam atividades individualmente ou em regime de economia familiar, na qualidade de pequenos produtores, proprietários, posseiros, assentados, meeiros, parceiros, arrendatários, comodatários e extrativistas, tendo como representação o somatório das Categorias e Bases Territoriais dos Sindicatos a ela Filiados. | AB233: 30150-250 | AC233: MG | AD233: Belo Horizonte | AE233: Santa Efigênia | AF233: Rua Álvares Maciel | AG233: 154 | AH233: Santa Efigênia | AI233: fetaemg@fetaemg.org.br | AJ233: 3130730000 | AK233: www.fetaemg.org.br | AL233: 14/06/2023 | AM233: 13/06/2027 | AN233: VILSON LUIZ DA SILVA | AO233: ESTADUAL | AP233: Minas Gerais
A234: =_xlfn.XLOOKUP(AD234,'Municipios MG'!$B$2:$B$853,'Municipios MG'!$A$2:$A$853) -> 3108701 | B234: =_xlfn.XLOOKUP(AD234,'Municipios MG'!$B$2:$B$853,'Municipios MG'!$B$2:$B$853) -> Brás Pires | C234: =_xlfn.XLOOKUP(AD234,'Municipios MG'!$B$2:$B$853,'Municipios MG'!$C$2:$C$853) -> -20.848456 | D234: =_xlfn.XLOOKUP(AD234,'Municipios MG'!$B$2:$B$853,'Municipios MG'!$D$2:$D$853) -> -43.239123 | E234: =_xlfn.XLOOKUP(A234,Planilha3!$A$2:$A$5543,Planilha3!$C$2:$C$5543) -> ... | F234: =_xlfn.XLOOKUP(A234,Planilha3!$A$2:$A$5543,Planilha3!$E$2:$E$5543) -> ... | H234: 18.129.353/0001-51 | I234: ATIVO | J234: SINDICATO | K234: STR BRAS PIRES - SINDICATO DOS TRABALHADORES RURAIS DE BRAS PIRES/MG | L234: SINDICATO DOS TRABALHADORES RURAIS DE BRAS PIRES | M234: 000.000.000.00000-0 | N234: - | O234: - | P234: - | Q234: PRESIDENCIALISMO | R234: 12 | S234: 381 | T234: DECISAO_ASSEMBLEIA | U234: 1 | V234: 2782 | W234: 396 | X234: RURAL | Y234: TRABALHADORES | Z234: RURAL | AA234: Profissional dos Trabalhadores Rurais, do Plano da CONTAG | AB234: 36542-000 | AC234: MG | AD234: Brás Pires | AE234: CENTRO | AF234: RUA JOAO DA CRUZ NUNES | AG234: 160 | AH234: CASA | AI234: strbraspires@yahoo.com.br | AJ234: 3235341173 | AK234: - | AL234: 06/01/2021 | AM234: 05/01/2025 | AN234: GERALDO CAMILO ARAUJO | AO234: MUNICIPAL | AP234: Minas Gerais: Brás Pires
A235: =_xlfn.XLOOKUP(AD235,'Municipios MG'!$B$2:$B$853,'Municipios MG'!$A$2:$A$853) -> 3115474 | B235: =_xlfn.XLOOKUP(AD235,'Municipios MG'!$B$2:$B$853,'Municipios MG'!$B$2:$B$853) -> Catuti | C235: =_xlfn.XLOOKUP(AD235,'Municipios MG'!$B$2:$B$853,'Municipios MG'!$C$2:$C$853) -> -15.357379 | D235: =_xlfn.XLOOKUP(AD235,'Municipios MG'!$B$2:$B$853,'Municipios MG'!$D$2:$D$853) -> -42.963523 | E235: =_xlfn.XLOOKUP(A235,Planilha3!$A$2:$A$5543,Planilha3!$C$2:$C$5543) -> ... | F235: =_xlfn.XLOOKUP(A235,Planilha3!$A$2:$A$5543,Planilha3!$E$2:$E$5543) -> ... | H235: 26.354.614/0001-65 | I235: ATIVO | J235: SINDICATO | K235: Sindicato dos Trabalhadores e Trabalhadoras Rurais do Município de Catuti/MG | L235: SINDICATO DOS TRABALHADORES E TRABALHADORAS RURAIS DO MUNICI | M235: 000.000.000.00000-0 | N235: - | O235: - | P235: - | Q235: PRESIDENCIALISMO | R235: 11 | S235: 74 | T235: DECISAO_ASSEMBLEIA | U235: 1 | V235: 143 | W235: 74 | X235: RURAL | Y235: TRABALHADORES | Z235: RURAL | AA235: Profissional dos Trabalhadores e Trabalhadoras Rurais, assalariados e assalariadas rurais, empregados permanentes, safristas_x000D_ e eventuais na agricultura, criação de animais e hortifruticultura; e agricultores e_x000D_ agricultoras que exerçam atividades individualmente ou em regime de economia familiar,_x000D_ na qualidade de pequenos produtores, proprietários até dois módulos rurais, posseiros,_x000D_ assentados, meeiros, parceiros, arrendatários, comodatários e os aposentados (as) rurais. | AB235: 39526-000 | AC235: MG | AD235: Catuti | AE235: CENTRO | AF235: PRAÇA PRESIDENTE VARGAS | AG235: 60 | AH235: CASA | AI235: sindicatocatuti@yahoo.com | AJ235: 38999328207 | AK235: - | AL235: 01/07/2022 | AM235: 30/06/2026 | AN235: JOAO ELTON SILVEIRA | AO235: MUNICIPAL | AP235: Minas Gerais: Catuti
A236: =_xlfn.XLOOKUP(AD236,'Municipios MG'!$B$2:$B$853,'Municipios MG'!$A$2:$A$853) -> 3123106 | B236: =_xlfn.XLOOKUP(AD236,'Municipios MG'!$B$2:$B$853,'Municipios MG'!$B$2:$B$853) -> Dores de Guanhães | C236: =_xlfn.XLOOKUP(AD236,'Municipios MG'!$B$2:$B$853,'Municipios MG'!$C$2:$C$853) -> -19.054262 | D236: =_xlfn.XLOOKUP(AD236,'Municipios MG'!$B$2:$B$853,'Municipios MG'!$D$2:$D$853) -> -42.926722 | E236: =_xlfn.XLOOKUP(A236,Planilha3!$A$2:$A$5543,Planilha3!$C$2:$C$5543) -> ... | F236: =_xlfn.XLOOKUP(A236,Planilha3!$A$2:$A$5543,Planilha3!$E$2:$E$5543) -> ... | H236: 19.210.996/0001-98 | I236: ATIVO | J236: SINDICATO | K236: STR - STRDORESGUANHAES | L236: SINDICATO DOS TRABALHADORES RURAIS DE DORES DE GUANHAES/MG | M236: 000.000.000.00000-0 | N236: CTB - Central dos Trabalhadores e Trabalhadoras do Brasil | O236: Confederação Nacional dos Trabalhadores Rurais Agricultores e Agricultoras Familiares | P236: FETAEMG - Federação dos Trabalhadores na Agricultura do Estado de Minas Gerais | Q236: PRESIDENCIALISMO | R236: 15 | S236: 94 | T236: DIRETA | U236: 1 | V236: 500 | W236: 94 | X236: RURAL | Y236: TRABALHADORES | Z236: RURAL | AA236: Profissional, dos Trabalhadores Rurais do plano da CONTAG | AB236: 35894-000 | AC236: MG | AD236: Dores de Guanhães | AE236: Centro | AF236: Travessa Bias Fortes | AG236: 122 | AH236: - | AI236: sindicatodoresdeguanhaes@yahoo.com.br | AJ236: 3334261395 | AK236: - | AL236: 09/04/2022 | AM236: 08/04/2026 | AN236: GERALDO JULIO DAMIAO | AO236: MUNICIPAL | AP236: Minas Gerais: Dores de Guanhães
A237: =_xlfn.XLOOKUP(AD237,'Municipios MG'!$B$2:$B$853,'Municipios MG'!$A$2:$A$853) -> 3129657 | B237: =_xlfn.XLOOKUP(AD237,'Municipios MG'!$B$2:$B$853,'Municipios MG'!$B$2:$B$853) -> Ibiracatu | C237: =_xlfn.XLOOKUP(AD237,'Municipios MG'!$B$2:$B$853,'Municipios MG'!$C$2:$C$853) -> -15.665467 | D237: =_xlfn.XLOOKUP(AD237,'Municipios MG'!$B$2:$B$853,'Municipios MG'!$D$2:$D$853) -> -44.167709 | E237: =_xlfn.XLOOKUP(A237,Planilha3!$A$2:$A$5543,Planilha3!$C$2:$C$5543) -> ... | F237: =_xlfn.XLOOKUP(A237,Planilha3!$A$2:$A$5543,Planilha3!$E$2:$E$5543) -> ... | H237: 07.371.820/0001-39 | I237: ATIVO | J237: SINDICATO | K237: SINDICATO DOS TRABALHADORES RURAIS DE IBIRACATU-MG | L237: SINDICATO DOS TRABALHADORES RURAIS DE IBIRACATU | M237: 000.000.000.00000-0 | N237: - | O237: - | P237: - | Q237: PRESIDENCIALISMO | R237: 12 | S237: 115 | T237: DIRETA | U237: 1 | V237: 115 | W237: 115 | X237: RURAL | Y237: TRABALHADORES | Z237: RURAL | AA237: Profissional dos Trabalhadores e Trabalhadoras rurais: assalariados e assalariadas rurais, empregados permanentes, safristas e eventuais na agricultura, criação de animais e hortifruticultura; e agricultores e agricultoras que exerçam atividades individualmente ou em regime de economia familiar, na qualidade de pequenos produtores, proprietários até dois módulos rurais, posseiros, assentados, meeiros, parceiros, arrendatários, comodatários e os aposenados(as) rurais. | AB237: 39455-000 | AC237: MG | AD237: Ibiracatu | AE237: CENTRO | AF237: RUA JOAO CARDOSO GOUDINHO | AG237: 104 | AH237: A | AI237: strdeibiracatu@yahoo.com.br | AJ237: 3836257167 | AK237: - | AL237: 25/07/2023 | AM237: 24/07/2027 | AN237: MARIA APARECIDA TEIXEIRA DOS SANTOS | AO237: MUNICIPAL | AP237: Minas Gerais: Ibiracatu
A238: =_xlfn.XLOOKUP(AD238,'Municipios MG'!$B$2:$B$853,'Municipios MG'!$A$2:$A$853) -> 3136959 | B238: =_xlfn.XLOOKUP(AD238,'Municipios MG'!$B$2:$B$853,'Municipios MG'!$B$2:$B$853) -> Juvenília | C238: =_xlfn.XLOOKUP(AD238,'Municipios MG'!$B$2:$B$853,'Municipios MG'!$C$2:$C$853) -> -14.263595 | D238: =_xlfn.XLOOKUP(AD238,'Municipios MG'!$B$2:$B$853,'Municipios MG'!$D$2:$D$853) -> -44.15959 | E238: =_xlfn.XLOOKUP(A238,Planilha3!$A$2:$A$5543,Planilha3!$C$2:$C$5543) -> ... | F238: =_xlfn.XLOOKUP(A238,Planilha3!$A$2:$A$5543,Planilha3!$E$2:$E$5543) -> ... | H238: 04.157.776/0001-70 | I238: ATIVO | J238: SINDICATO | K238: SINDICATO DOS TRABALHADORES RURAIS DE JUVENILIA - SINDICATO DOS TRABALHADORES RURAIS DE JUVENILIA | L238: SINDICATO DOS TRABALHADORES RURAIS DE JUVENILIA | M238: 000.000.000.00000-0 | N238: - | O238: - | P238: - | Q238: PRESIDENCIALISMO | R238: 8 | S238: 104 | T238: DIRETA | U238: 1 | V238: 2339 | W238: 109 | X238: RURAL | Y238: TRABALHADORES | Z238: RURAL | AA238: TRABALHADORES RURAIS | AB238: 39467-000 | AC238: MG | AD238: JUVENÍLIA | AE238: CENTRO | AF238: RUA BERNARDO DA FONSECA PINTO | AG238: 378 | AH238: A | AI238: strjuvenilia.mg@hotmail.com | AJ238: 3836149230 | AK238: - | AL238: 03/03/2021 | AM238: 03/03/2025 | AN238: SEBASTIAO ANTONIO DE SOUZA | AO238: MUNICIPAL | AP238: Minas Gerais: Juvenília
A239: =_xlfn.XLOOKUP(AD239,'Municipios MG'!$B$2:$B$853,'Municipios MG'!$A$2:$A$853) -> 3138658 | B239: =_xlfn.XLOOKUP(AD239,'Municipios MG'!$B$2:$B$853,'Municipios MG'!$B$2:$B$853) -> Lontra | C239: =_xlfn.XLOOKUP(AD239,'Municipios MG'!$B$2:$B$853,'Municipios MG'!$C$2:$C$853) -> -15.902058 | D239: =_xlfn.XLOOKUP(AD239,'Municipios MG'!$B$2:$B$853,'Municipios MG'!$D$2:$D$853) -> -44.306115 | E239: =_xlfn.XLOOKUP(A239,Planilha3!$A$2:$A$5543,Planilha3!$C$2:$C$5543) -> ... | F239: =_xlfn.XLOOKUP(A239,Planilha3!$A$2:$A$5543,Planilha3!$E$2:$E$5543) -> ... | H239: 11.230.237/0001-85 | I239: ATIVO | J239: SINDICATO | K239: Sindicato dos Trabalhadores e Trabalhadoras Rurais de Lontra - MG | L239: SINDICATO DOS TRABALHADORES E TRABALHADORAS RURAIS DE LONTRA | M239: 000.000.000.00000-0 | N239: - | O239: - | P239: - | Q239: PRESIDENCIALISMO | R239: 12 | S239: 237 | T239: DECISAO_ASSEMBLEIA | U239: 1 | V239: 1021 | W239: 238 | X239: RURAL | Y239: TRABALHADORES | Z239: RURAL | AA239: Trabalhadores e trabalhadoras rurais: Assalariados e assalariadas rurais, empregados permanentes, safristas e eventuais na agricultura, criação de animais, silvicultura, hortifruticultura e extrativismo rural; e agricultores e_x000D_ agricultoras que exerçam atividades individualmente ou em regime de economia familiar, na qualidade de pequenos produtores, proprietários, posseiros, assentados, meeiros, parceiros, arrendatários, comodatários, extrativistas e os aposentados rurais, nos termos do Decreto 1166/71. | AB239: 39437-000 | AC239: MG | AD239: Lontra | AE239: - | AF239: Av. Belo Horizonte | AG239: 493 | AH239: Centro | AI239: moradamy@hotmail.com | AJ239: 3832348222 | AK239: - | AL239: 05/02/2022 | AM239: 05/02/2026 | AN239: SILVANO ANTONIO DE FREITAS | AO239: MUNICIPAL | AP239: Minas Gerais: Lontra
A240: =_xlfn.XLOOKUP(AD240,'Municipios MG'!$B$2:$B$853,'Municipios MG'!$A$2:$A$853) -> 3145208 | B240: =_xlfn.XLOOKUP(AD240,'Municipios MG'!$B$2:$B$853,'Municipios MG'!$B$2:$B$853) -> Nova Serrana | C240: =_xlfn.XLOOKUP(AD240,'Municipios MG'!$B$2:$B$853,'Municipios MG'!$C$2:$C$853) -> -19.875867 | D240: =_xlfn.XLOOKUP(AD240,'Municipios MG'!$B$2:$B$853,'Municipios MG'!$D$2:$D$853) -> -44.985579 | E240: =_xlfn.XLOOKUP(A240,Planilha3!$A$2:$A$5543,Planilha3!$C$2:$C$5543) -> ... | F240: =_xlfn.XLOOKUP(A240,Planilha3!$A$2:$A$5543,Planilha3!$E$2:$E$5543) -> ... | H240: 18.707.703/0001-10 | I240: INATIVO | J240: SINDICATO | K240: Sindicato dos Trabalhadores Rurais de Nova Serrana | L240: SINDICATO DOS TRABALHADORES RURAIS DE NOVA SERRANA | M240: 000.000.000.00000-0 | N240: FS - Força Sindical | O240: Confederação Nacional dos Trabalhadores Rurais Agricultores e Agricultoras Familiares | P240: FETAEMG - Federação dos Trabalhadores na Agricultura do Estado de Minas Gerais | Q240: PRESIDENCIALISMO | R240: 13 | S240: 45 | T240: DIRETA | U240: 1 | V240: 85 | W240: 47 | X240: RURAL | Y240: TRABALHADORES | Z240: RURAL | AA240: Profissional dos Trabalhadores Rurais, do Plano da CONTAG; | AB240: 35519-000 | AC240: MG | AD240: Nova Serrana | AE240: Frei Paulo | AF240: Rua Paraiba | AG240: 31 | AH240: - | AI240: sindtrabrural@digimaster.com.br | AJ240: 3732261171 | AK240: - | AL240: 06/06/2009 | AM240: 06/06/2012 | AN240: GERALDO MAGELA VIEGAS | AO240: MUNICIPAL | AP240: Minas Gerais: Nova Serrana
A241: =_xlfn.XLOOKUP(AD241,'Municipios MG'!$B$2:$B$853,'Municipios MG'!$A$2:$A$853) -> 3155009 | B241: =_xlfn.XLOOKUP(AD241,'Municipios MG'!$B$2:$B$853,'Municipios MG'!$B$2:$B$853) -> Rio Doce | C241: =_xlfn.XLOOKUP(AD241,'Municipios MG'!$B$2:$B$853,'Municipios MG'!$C$2:$C$853) -> -20.244646 | D241: =_xlfn.XLOOKUP(AD241,'Municipios MG'!$B$2:$B$853,'Municipios MG'!$D$2:$D$853) -> -42.895681 | E241: =_xlfn.XLOOKUP(A241,Planilha3!$A$2:$A$5543,Planilha3!$C$2:$C$5543) -> ... | F241: =_xlfn.XLOOKUP(A241,Planilha3!$A$2:$A$5543,Planilha3!$E$2:$E$5543) -> ... | H241: 07.627.616/0001-36 | I241: INATIVO | J241: SINDICATO | K241: sindro - sindicato dos trabalhadores rurais de rio doce-mg | L241: SINDICATO DOS TRABALHADORES RURAIS DE RIO DOCE | M241: 000.000.000.00000-0 | N241: CENTRAL DO BRASIL DEMOCRATICA DE TRABALHADORES - CBDT NACIONAL | O241: Confederação Nacional dos Trabalhadores Rurais Agricultores e Agricultoras Familiares | P241: - | Q241: PRESIDENCIALISMO | R241: 14 | S241: 42 | T241: DIRETA | U241: 1 | V241: 73 | W241: 42 | X241: RURAL | Y241: TRABALHADORES | Z241: RURAL | AA241: Profissional dos Trabalhadores Rurais, plano da CONTAG | AB241: 35442-000 | AC241: MG | AD241: Rio Doce | AE241: centro | AF241: rua Major eugenio palermo | AG241: 102 | AH241: - | AI241: - | AJ241: 3138835139 | AK241: - | AL241: 19/06/2009 | AM241: 19/06/2013 | AN241: NOE CORCINI CAMPOS | AO241: MUNICIPAL | AP241: Minas Gerais: Rio Doce
A242: =_xlfn.XLOOKUP(AD242,'Municipios MG'!$B$2:$B$853,'Municipios MG'!$A$2:$A$853) -> 3157609 | B242: =_xlfn.XLOOKUP(AD242,'Municipios MG'!$B$2:$B$853,'Municipios MG'!$B$2:$B$853) -> Santa Fé de Minas | C242: =_xlfn.XLOOKUP(AD242,'Municipios MG'!$B$2:$B$853,'Municipios MG'!$C$2:$C$853) -> -16.687373 | D242: =_xlfn.XLOOKUP(AD242,'Municipios MG'!$B$2:$B$853,'Municipios MG'!$D$2:$D$853) -> -45.413633 | E242: =_xlfn.XLOOKUP(A242,Planilha3!$A$2:$A$5543,Planilha3!$C$2:$C$5543) -> ... | F242: =_xlfn.XLOOKUP(A242,Planilha3!$A$2:$A$5543,Planilha3!$E$2:$E$5543) -> ... | H242: 02.670.864/0001-46 | I242: ATIVO | J242: SINDICATO | K242: Sindicato dos Trabalhadores Rurais de Santa Fé de Minas/MG | L242: SINDICATO DOS TRABALHADORES RURAIS DE SANTA FE DE MINAS | M242: 000.000.000.00000-0 | N242: - | O242: - | P242: - | Q242: PRESIDENCIALISMO | R242: 15 | S242: 15 | T242: DIRETA | U242: 1 | V242: 15 | W242: 15 | X242: RURAL | Y242: TRABALHADORES | Z242: RURAL | AA242: Profissional dos trabalhadores e trabalhadoras rurais: assalariados e assalariadas rurais, empregados permanentes, safristas e eventuais na agricultura, criação de animais e hortifruticultura; e agricultores e agricultoras que exerçam atividades individualmente ou em regime de economia familiar, na qualidade de pequenos produtores, proprietários até dois módulos rurais (Decreto 1166/71), posseiros, assentados, meeiros, parceiros, arrendatários, comodatários e os aposentados(as) rurais. | AB242: 39295-000 | AC242: MG | AD242: Santa Fé de Minas | AE242: Centro | AF242: Av. Belo Horizonte | AG242: 1816 | AH242: Santa Cruz | AI242: adailtontotoca@yahoo.com.br | AJ242: 3836321176 | AK242: - | AL242: 20/04/2020 | AM242: 20/04/2024 | AN242: MAURILIO GONCALVES DA SILVA | AO242: MUNICIPAL | AP242: Minas Gerais: Santa Fé de Minas
A243: =_xlfn.XLOOKUP(AD243,'Municipios MG'!$B$2:$B$853,'Municipios MG'!$A$2:$A$853) -> 3164209 | B243: =_xlfn.XLOOKUP(AD243,'Municipios MG'!$B$2:$B$853,'Municipios MG'!$B$2:$B$853) -> São Romão | C243: =_xlfn.XLOOKUP(AD243,'Municipios MG'!$B$2:$B$853,'Municipios MG'!$C$2:$C$853) -> -16.368639 | D243: =_xlfn.XLOOKUP(AD243,'Municipios MG'!$B$2:$B$853,'Municipios MG'!$D$2:$D$853) -> -45.069135 | E243: =_xlfn.XLOOKUP(A243,Planilha3!$A$2:$A$5543,Planilha3!$C$2:$C$5543) -> ... | F243: =_xlfn.XLOOKUP(A243,Planilha3!$A$2:$A$5543,Planilha3!$E$2:$E$5543) -> ... | H243: 21.366.745/0001-49 | I243: ATIVO | J243: SINDICATO | K243: STR São Romão/MG - Sindicato dos Trabalhadores Rurais de São Romão/MG | L243: SINDICATO DOS TRABALHADORES RURAIS DE SAO ROMAO | M243: 000.000.000.00000-0 | N243: - | O243: Confederação Nacional dos Trabalhadores Rurais Agricultores e Agricultoras Familiares | P243: FETAEMG - Federação dos Trabalhadores na Agricultura do Estado de Minas Gerais | Q243: PRESIDENCIALISMO | R243: 12 | S243: 60 | T243: DIRETA | U243: 1 | V243: 5016 | W243: 61 | X243: RURAL | Y243: TRABALHADORES | Z243: RURAL | AA243: Trabalhadores rurais | AB243: 39290-000 | AC243: MG | AD243: São Romão | AE243: - | AF243: Av. Eustáquio Martins | AG243: 400 | AH243: centro | AI243: strsaoromao@hotmail.com | AJ243: 3836241532 | AK243: - | AL243: 18/02/2026 | AM243: 18/02/2030 | AN243: LILIAN ALVES DOS SANTOS | AO243: MUNICIPAL | AP243: Minas Gerais: São Romão
A244: =_xlfn.XLOOKUP(AD244,'Municipios MG'!$B$2:$B$853,'Municipios MG'!$A$2:$A$853) -> 3171006 | B244: =_xlfn.XLOOKUP(AD244,'Municipios MG'!$B$2:$B$853,'Municipios MG'!$B$2:$B$853) -> Vazante | C244: =_xlfn.XLOOKUP(AD244,'Municipios MG'!$B$2:$B$853,'Municipios MG'!$C$2:$C$853) -> -17.991038 | D244: =_xlfn.XLOOKUP(AD244,'Municipios MG'!$B$2:$B$853,'Municipios MG'!$D$2:$D$853) -> -46.901967 | E244: =_xlfn.XLOOKUP(A244,Planilha3!$A$2:$A$5543,Planilha3!$C$2:$C$5543) -> ... | F244: =_xlfn.XLOOKUP(A244,Planilha3!$A$2:$A$5543,Planilha3!$E$2:$E$5543) -> ... | H244: 02.074.018/0001-63 | I244: INATIVO | J244: SINDICATO | K244: straafv - Sindicato dos Trabalhadores Rurais,Assalariados e Agricultores Familiares do Município de Varzante - MG | L244: SINDICATO DOS TRABALHADORES RURAIS, ASSALARIADOS E AGRICULTO | M244: 000.000.000.00000-0 | N244: - | O244: Confederação Nacional dos Trabalhadores Rurais Agricultores e Agricultoras Familiares | P244: FETAEMG - Federação dos Trabalhadores na Agricultura do Estado de Minas Gerais | Q244: PRESIDENCIALISMO | R244: 15 | S244: 136 | T244: DIRETA | U244: 1 | V244: 242 | W244: 186 | X244: RURAL | Y244: TRABALHADORES | Z244: RURAL | AA244: Profissional dos Trabalhadores(as) Rurais, Empregados (as)Rurais e Agricultores Familiares, Ativos (as) e Aposentados (as).São considerados Trabalhadores Rurais, os que exercem atividade como assalariados na Agricultura, Pecuária e similares, na Produção Rural, bem como os Agricultores Familiares, proprietários ou não, que exerçam atividade Rural, Individualmente ou em Regime de Economia Familiar, assim entendido o trabalho dos membros da mesma família, executado em condições de mútua dependência e colaboração, ainda que com ajuda eventual de terceiros, Trabalhadores no Reflorestamento, Hortifrutigranjeiros, Assentados e parceleiros da Reforma Agrária, Pescadores e Garimpeiros Artesanais que Trabalham por conta própria e não tenham Empregados, Trabalhadores na Área da Cana e da Avicultura, Tratorista Rural e os que Trabalham com Artesanato Rural | AB244: 38780-000 | AC244: MG | AD244: Vazante | AE244: Centro | AF244: Rua : Joao Claudio | AG244: 107 | AH244: Casa | AI244: strvazante@gmail.com.br | AJ244: 3438131510 | AK244: - | AL244: 05/01/2010 | AM244: 01/01/2014 | AN244: ELICIA FERREIRA DO PRADO | AO244: MUNICIPAL | AP244: Minas Gerais: Vazante
... A282: =_xlfn.XLOOKUP(AD282,'Municipios MG'!$B$2:$B$853,'Municipios MG'!$A$2:$A$853) -> 3119401 | B282: =_xlfn.XLOOKUP(AD282,'Municipios MG'!$B$2:$B$853,'Municipios MG'!$B$2:$B$853) -> Coronel Fabriciano | C282: =_xlfn.XLOOKUP(AD282,'Municipios MG'!$B$2:$B$853,'Municipios MG'!$C$2:$C$853) -> -19.525053 | D282: =_xlfn.XLOOKUP(AD282,'Municipios MG'!$B$2:$B$853,'Municipios MG'!$D$2:$D$853) -> -42.624347 | E282: =_xlfn.XLOOKUP(A282,Planilha3!$A$2:$A$5543,Planilha3!$C$2:$C$5543) -> - | F282: =_xlfn.XLOOKUP(A282,Planilha3!$A$2:$A$5543,Planilha3!$E$2:$E$5543) -> - | H282: 21.449.768/0001-17 | I282: ATIVO | J282: SINDICATO | K282: STR Coronel Fabricano - Sindicato dos Trabalhadores Rurais de Coronel Fabriciano | L282: SINDICATO DOS TRABALHADORES RURAIS DE CORONEL FABRICIANO | M282: 000.000.000.00000-0 | N282: - | O282: - | P282: - | Q282: PRESIDENCIALISMO | R282: 15 | S282: 26 | T282: DECISAO_ASSEMBLEIA | U282: 1 | V282: 26 | W282: 26 | X282: RURAL | Y282: TRABALHADORES | Z282: RURAL | AA282: Trabalhadores e trabalhadoras rurais: assalariados e assalariadas rurais, empregados permanentes, safristas e eventuais na agricultura, criação de animais e hortifruticultura; e agricultores e agricultoras que exerçam atividades individualmente ou em regime de economia familiar, na qualidades de pequenos produtores, proprietários ate dois módulos rurais, posseiros, assentados, meeiros, parceiros, arrendatários, comodatários e os aposentados (as) rurais. | AB282: 35171-353 | AC282: MG | AD282: Coronel Fabriciano | AE282: Sylvio Pereira I | AF282: Rua Osvaldina Vieira Mota | AG282: 52 | AH282: - | AI282: sintrucelf@outloo.com | AJ282: 3138468733 | AK282: - | AL282: 16/06/2016 | AM282: 15/06/2020 | AN282: JOSE PEREIRA DE MOURA | AO282: INTERMUNICIPAL | AP282: Minas Gerais: Antônio Dias, Coronel Fabriciano, Jaguaraçu, Marliéria
A283: =_xlfn.XLOOKUP(AD283,'Municipios MG'!$B$2:$B$853,'Municipios MG'!$A$2:$A$853) -> 3119500 | B283: =_xlfn.XLOOKUP(AD283,'Municipios MG'!$B$2:$B$853,'Municipios MG'!$B$2:$B$853) -> Coronel Murta | C283: =_xlfn.XLOOKUP(AD283,'Municipios MG'!$B$2:$B$853,'Municipios MG'!$C$2:$C$853) -> -16.610268 | D283: =_xlfn.XLOOKUP(AD283,'Municipios MG'!$B$2:$B$853,'Municipios MG'!$D$2:$D$853) -> -42.184804 | E283: =_xlfn.XLOOKUP(A283,Planilha3!$A$2:$A$5543,Planilha3!$C$2:$C$5543) -> - | F283: =_xlfn.XLOOKUP(A283,Planilha3!$A$2:$A$5543,Planilha3!$E$2:$E$5543) -> - | H283: 06.531.793/0001-51 | I283: INATIVO | J283: SINDICATO | K283: Sindicato dos Garimpeiros de Coronel Murta e do Médio Jequitinhonha”,MG | L283: SINDICATO DOS GARIMPEIROS DE CORONEL MURTA E DO MEDIO JEQUITINHONHA | M283: 000.000.000.00000-0 | N283: - | O283: - | P283: - | Q283: COLEGIADA | R283: - | S283: - | T283: - | U283: - | V283: 0 | W283: - | X283: RURAL | Y283: TRABALHADORES | Z283: RURAL | AA283: Profissional dos Garimpeiros | AB283: 39635-000 | AC283: MG | AD283: Coronel Murta | AE283: Centro | AF283: Inacio Figueiredo | AG283: 127 | AH283: - | AI283: pmcmurta@pop.com.br | AJ283: 3337351442 | AK283: - | AL283: 08/02/2007 | AM283: 08/02/2010 | AN283: - | AO283: INTERMUNICIPAL | AP283: Minas Gerais: Araçuaí, Coronel Murta, Itaobim, Itinga, Rubelita, Salinas, Virgem da Lapa
A284: =_xlfn.XLOOKUP(AD284,'Municipios MG'!$B$2:$B$853,'Municipios MG'!$A$2:$A$853) -> 3119500 | B284: =_xlfn.XLOOKUP(AD284,'Municipios MG'!$B$2:$B$853,'Municipios MG'!$B$2:$B$853) -> Coronel Murta | C284: =_xlfn.XLOOKUP(AD284,'Municipios MG'!$B$2:$B$853,'Municipios MG'!$C$2:$C$853) -> -16.610268 | D284: =_xlfn.XLOOKUP(AD284,'Municipios MG'!$B$2:$B$853,'Municipios MG'!$D$2:$D$853) -> -42.184804 | E284: =_xlfn.XLOOKUP(A284,Planilha3!$A$2:$A$5543,Planilha3!$C$2:$C$5543) -> - | F284: =_xlfn.XLOOKUP(A284,Planilha3!$A$2:$A$5543,Planilha3!$E$2:$E$5543) -> - | H284: 18.355.214/0001-46 | I284: ATIVO | J284: SINDICATO | K284: STR de Coronel Murta - Sindicato dos Trabalhadores Rurais de Corone | L284: SINDICATO DOS TRABALHADORES RURAIS DE CORONEL MURTA | M284: 000.000.000.00000-0 | N284: - | O284: Confederação Nacional dos Trabalhadores Rurais Agricultores e Agricultoras Familiares | P284: FETAEMG - Federação dos Trabalhadores na Agricultura do Estado de Minas Gerais | Q284: PRESIDENCIALISMO | R284: 5 | S284: 436 | T284: DIRETA | U284: 2 | V284: 3956 | W284: 1005 | X284: RURAL | Y284: TRABALHADORES | Z284: RURAL | AA284: Profissional, dos Trabalhadores Rurais do Plano da CONTAG | AB284: 39635-000 | AC284: MG | AD284: Coronel Murta | AE284: Centro | AF284: Rua Rita Murta | AG284: 27 | AH284: Sede | AI284: strmurta@yahoo.com.br | AJ284: 3337351211 | AK284: - | AL284: 01/01/2022 | AM284: 31/12/2025 | AN284: AUXILIADORA ALVES MARTINS | AO284: MUNICIPAL | AP284: Minas Gerais: Coronel Murta
A285: =_xlfn.XLOOKUP(AD285,'Municipios MG'!$B$2:$B$853,'Municipios MG'!$A$2:$A$853) -> 3120607 | B285: =_xlfn.XLOOKUP(AD285,'Municipios MG'!$B$2:$B$853,'Municipios MG'!$B$2:$B$853) -> Crucilândia | C285: =_xlfn.XLOOKUP(AD285,'Municipios MG'!$B$2:$B$853,'Municipios MG'!$C$2:$C$853) -> -20.393292 | D285: =_xlfn.XLOOKUP(AD285,'Municipios MG'!$B$2:$B$853,'Municipios MG'!$D$2:$D$853) -> -44.337837 | E285: =_xlfn.XLOOKUP(A285,Planilha3!$A$2:$A$5543,Planilha3!$C$2:$C$5543) -> - | F285: =_xlfn.XLOOKUP(A285,Planilha3!$A$2:$A$5543,Planilha3!$E$2:$E$5543) -> - | H285: 19.164.110/0001-17 | I285: ATIVO | J285: SINDICATO | K285: Sindicato dos Trabalhadores Rurais de Crucilândia | L285: SINDICATO DOS TRABALHADORES RURAIS DE CRUCILANDIA | M285: 000.000.000.00000-0 | N285: CENTRAL DO BRASIL DEMOCRATICA DE TRABALHADORES - CBDT NACIONAL | O285: Confederação Nacional dos Trabalhadores Rurais Agricultores e Agricultoras Familiares | P285: FETAEMG - Federação dos Trabalhadores na Agricultura do Estado de Minas Gerais | Q285: PRESIDENCIALISMO | R285: 12 | S285: 221 | T285: DECISAO_ASSEMBLEIA | U285: 2 | V285: 1861 | W285: 329 | X285: RURAL | Y285: TRABALHADORES | Z285: RURAL | AA285: Profissionais, dos Trabalhadores Rurais do plano da CONTAG. | AB285: 35520-000 | AC285: MG | AD285: Crucilândia | AE285: Centro | AF285: Rua Luiz Alves de Souza | AG285: 09 | AH285: casa | AI285: strcruci@ig.com.br | AJ285: 3135741132 | AK285: - | AL285: 19/12/2020 | AM285: 18/12/2024 | AN285: LUIZ CARLOS DINIZ | AO285: MUNICIPAL | AP285: Minas Gerais: Crucilândia
A286: =_xlfn.XLOOKUP(AD286,'Municipios MG'!$B$2:$B$853,'Municipios MG'!$A$2:$A$853) -> 3120904 | B286: =_xlfn.XLOOKUP(AD286,'Municipios MG'!$B$2:$B$853,'Municipios MG'!$B$2:$B$853) -> Curvelo | C286: =_xlfn.XLOOKUP(AD286,'Municipios MG'!$B$2:$B$853,'Municipios MG'!$C$2:$C$853) -> -18.755481 | D286: =_xlfn.XLOOKUP(AD286,'Municipios MG'!$B$2:$B$853,'Municipios MG'!$D$2:$D$853) -> -44.428399 | E286: =_xlfn.XLOOKUP(A286,Planilha3!$A$2:$A$5543,Planilha3!$C$2:$C$5543) -> - | F286: =_xlfn.XLOOKUP(A286,Planilha3!$A$2:$A$5543,Planilha3!$E$2:$E$5543) -> - | H286: 04.650.348/0001-85 | I286: ATIVO | J286: SINDICATO | K286: Sindicato dos Empregados Rurais de de Curvelo", MG. | L286: SINDICATO DOS TRABALHADORES E TRABALHADORAS RURAIS DE CURVELO-MG | M286: 000.000.000.00000-0 | N286: CUT - Central Única dos Trabalhadores | O286: - | P286: - | Q286: PRESIDENCIALISMO | R286: 11 | S286: 140 | T286: DECISAO_ASSEMBLEIA | U286: 1 | V286: 3415 | W286: 140 | X286: RURAL | Y286: TRABALHADORES | Z286: RURAL | AA286: Trabalhadores rurais: assalariados e assalariadas rurais empregados permanentes, safrista e eventuais na agricultura, criação de animais, silvicultura, hortifruticultura e extrativismo rural; e agricultores e agricultoras que exerçam atividades individualmente ou em regime de economia familiar, na qualidade de pequenos produtores, proprietários, posseiros assentados meeiros, parceiros, arrendatário, comodatários e extrativista. | AB286: 35790-000 | AC286: MG | AD286: Curvelo | AE286: palmeiras | AF286: RUA:Campo alto | AG286: 268 | AH286: casa | AI286: strcurvelo@rznet.com.br | AJ286: 3837225718 | AK286: - | AL286: 09/07/2016 | AM286: 09/07/2021 | AN286: ROGERIO TAVARES LEITE | AO286: MUNICIPAL | AP286: Minas Gerais: Curvelo
A287: =_xlfn.XLOOKUP(AD287,'Municipios MG'!$B$2:$B$853,'Municipios MG'!$A$2:$A$853) -> 3121258 | B287: =_xlfn.XLOOKUP(AD287,'Municipios MG'!$B$2:$B$853,'Municipios MG'!$B$2:$B$853) -> Delta | C287: =_xlfn.XLOOKUP(AD287,'Municipios MG'!$B$2:$B$853,'Municipios MG'!$C$2:$C$853) -> -19.977473 | D287: =_xlfn.XLOOKUP(AD287,'Municipios MG'!$B$2:$B$853,'Municipios MG'!$D$2:$D$853) -> -47.772971 | E287: =_xlfn.XLOOKUP(A287,Planilha3!$A$2:$A$5543,Planilha3!$C$2:$C$5543) -> - | F287: =_xlfn.XLOOKUP(A287,Planilha3!$A$2:$A$5543,Planilha3!$E$2:$E$5543) -> - | H287: 04.142.910/0001-60 | I287: ATIVO | J287: SINDICATO | K287: STRDELTA - SINDICATO DOS TRABALHADORES RURAIS DE DELTA/MG | L287: SINDICATO DOS TRABALHADORES RURAIS E DO SETOR SUCROENERGETIC | M287: 000.000.000.00000-0 | N287: CTB - Central dos Trabalhadores e Trabalhadoras do Brasil | O287: - | P287: FETAEMG - Federação dos Trabalhadores na Agricultura do Estado de Minas Gerais | Q287: PRESIDENCIALISMO | R287: 12 | S287: 16 | T287: DECISAO_ASSEMBLEIA | U287: 1 | V287: 19 | W287: 16 | X287: RURAL | Y287: TRABALHADORES | Z287: RURAL | AA287: Trabalhadores Rurais, Empregados, Assalariados em Geral, que exercem atividades nos seguintes setores: Canavieiro, Citricultura, Cultura Diversificada, Granjeiros, Pecuária, Reflorestamento, Corte de Madeira e Extrativismo Rural | AB287: 38108-000 | AC287: MG | AD287: Delta | AE287: Centro | AF287: Rua Manoel Abadia da Silva | AG287: 378 | AH287: - | AI287: strdelta@netsite.com.br | AJ287: 3433251495 | AK287: - | AL287: 07/04/2020 | AM287: 06/04/2028 | AN287: EDILSO LEANDRO RIBEIRO | AO287: MUNICIPAL | AP287: Minas Gerais: Delta
A288: =_xlfn.XLOOKUP(AD288,'Municipios MG'!$B$2:$B$853,'Municipios MG'!$A$2:$A$853) -> 3121803 | B288: =_xlfn.XLOOKUP(AD288,'Municipios MG'!$B$2:$B$853,'Municipios MG'!$B$2:$B$853) -> Dionísio | C288: =_xlfn.XLOOKUP(AD288,'Municipios MG'!$B$2:$B$853,'Municipios MG'!$C$2:$C$853) -> -19.843997 | D288: =_xlfn.XLOOKUP(AD288,'Municipios MG'!$B$2:$B$853,'Municipios MG'!$D$2:$D$853) -> -42.782368 | E288: =_xlfn.XLOOKUP(A288,Planilha3!$A$2:$A$5543,Planilha3!$C$2:$C$5543) -> - | F288: =_xlfn.XLOOKUP(A288,Planilha3!$A$2:$A$5543,Planilha3!$E$2:$E$5543) -> - | H288: 05.195.955/0001-65 | I288: ATIVO | J288: SINDICATO | K288: STRD - SINDICATO DOS TRABALHADORES RURAIS DE DIONÍSIO | L288: SINDICATO DOS TRABALHADORES RURAIS DE DIONISIO | M288: 000.000.000.00000-0 | N288: CUT - Central Única dos Trabalhadores | O288: Confederação Nacional dos Trabalhadores Rurais Agricultores e Agricultoras Familiares | P288: FETAEMG - Federação dos Trabalhadores na Agricultura do Estado de Minas Gerais | Q288: PRESIDENCIALISMO | R288: 12 | S288: 45 | T288: DIRETA | U288: 1 | V288: 233 | W288: 45 | X288: RURAL | Y288: TRABALHADORES | Z288: RURAL | AA288: Profissional dos Trabalhadores Rurais, do Plano da CONTAG | AB288: 35984-000 | AC288: MG | AD288: Dionísio | AE288: Centro | AF288: Rua Senador Milton Campos | AG288: 136 | AH288: - | AI288: strdionisio@yahoo.com.br | AJ288: 3138581302 | AK288: - | AL288: 20/06/2023 | AM288: 20/06/2027 | AN288: ANTONIO CARLOS SILVA LEAO | AO288: MUNICIPAL | AP288: Minas Gerais: Dionísio
A289: =_xlfn.XLOOKUP(AD289,'Municipios MG'!$B$2:$B$853,'Municipios MG'!$A$2:$A$853) -> 3122306 | B289: =_xlfn.XLOOKUP(AD289,'Municipios MG'!$B$2:$B$853,'Municipios MG'!$B$2:$B$853) -> Divinópolis | C289: =_xlfn.XLOOKUP(AD289,'Municipios MG'!$B$2:$B$853,'Municipios MG'!$C$2:$C$853) -> -20.142074 | D289: =_xlfn.XLOOKUP(AD289,'Municipios MG'!$B$2:$B$853,'Municipios MG'!$D$2:$D$853) -> -44.893886 | E289: =_xlfn.XLOOKUP(A289,Planilha3!$A$2:$A$5543,Planilha3!$C$2:$C$5543) -> - | F289: =_xlfn.XLOOKUP(A289,Planilha3!$A$2:$A$5543,Planilha3!$E$2:$E$5543) -> - | H289: 20.169.355/0001-16 | I289: ATIVO | J289: SINDICATO | K289: STR - STR DIVINOPOLIS | L289: SINDICATO DOS TRABALHADORES RURAIS DE DIVINOPOLIS | M289: 000.000.000.00000-0 | N289: CENTRAL DO BRASIL DEMOCRATICA DE TRABALHADORES - CBDT NACIONAL | O289: Confederação Nacional dos Trabalhadores Rurais Agricultores e Agricultoras Familiares | P289: FETAEMG - Federação dos Trabalhadores na Agricultura do Estado de Minas Gerais | Q289: PRESIDENCIALISMO | R289: 12 | S289: 706 | T289: DIRETA | U289: 1 | V289: 13612 | W289: 725 | X289: RURAL | Y289: TRABALHADORES | Z289: RURAL | AA289: Profissional dos Trabalhadores Rurais, plano da CONTAG | AB289: 35500-022 | AC289: MG | AD289: Divinópolis | AE289: Centro | AF289: Rua Oeste de Minas | AG289: 36 | AH289: - | AI289: sinddivinopolis@gmail.com | AJ289: 3732147404 | AK289: - | AL289: 25/03/2022 | AM289: 25/03/2026 | AN289: JOSE ANTONIO RIBEIRO | AO289: INTERMUNICIPAL | AP289: Minas Gerais: Divinópolis, Pedra do Indaiá, Santo Antônio do Monte, São Sebastião do Oeste
A290: =_xlfn.XLOOKUP(AD290,'Municipios MG'!$B$2:$B$853,'Municipios MG'!$A$2:$A$853) -> 3122470 | B290: =_xlfn.XLOOKUP(AD290,'Municipios MG'!$B$2:$B$853,'Municipios MG'!$B$2:$B$853) -> Dom Bosco | C290: =_xlfn.XLOOKUP(AD290,'Municipios MG'!$B$2:$B$853,'Municipios MG'!$C$2:$C$853) -> -16.65075 | D290: =_xlfn.XLOOKUP(AD290,'Municipios MG'!$B$2:$B$853,'Municipios MG'!$D$2:$D$853) -> -46.27145 | E290: =_xlfn.XLOOKUP(A290,Planilha3!$A$2:$A$5543,Planilha3!$C$2:$C$5543) -> - | F290: =_xlfn.XLOOKUP(A290,Planilha3!$A$2:$A$5543,Planilha3!$E$2:$E$5543) -> - | H290: 03.800.566/0001-96 | I290: ATIVO | J290: SINDICATO | K290: STR - Sindicato dos Trabalhadores Rurais de Dom Bosco - MG | L290: SINDICATO DOS TRABAHADORES RURAIS DE DOM BOSCO - MG | M290: 000.000.000.00000-0 | N290: - | O290: Confederação Nacional dos Trabalhadores Rurais Agricultores e Agricultoras Familiares | P290: FETAEMG - Federação dos Trabalhadores na Agricultura do Estado de Minas Gerais | Q290: PRESIDENCIALISMO | R290: 15 | S290: 31 | T290: DIRETA | U290: 1 | V290: 498 | W290: 31 | X290: RURAL | Y290: TRABALHADORES | Z290: RURAL | AA290: Trabalhadores Rurais | AB290: 38654-000 | AC290: MG | AD290: Dom Bosco | AE290: Centro | AF290: Rua José Mendes | AG290: 489 | AH290: casa | AI290: sindicato.dombosco@hotmail.com | AJ290: 3836757147 | AK290: - | AL290: 17/05/2026 | AM290: 17/05/2030 | AN290: BEATRIZ HELENA RODRIGUES SOUZA | AO290: MUNICIPAL | AP290: Minas Gerais: Dom Bosco
